Workbook

Sheet Start Here
B2: ARUBA PROSPECT TRACKER
B3: Website sales pipeline — built August 2026
B6: HOW TO USE THIS FILE
B7: 1. | C7: Fill in the 'Prospects' tab. Blue text = cells you type in. Row 4 is an example — delete it once you start.
B8: 2. | C8: Log every business you find, WITH or WITHOUT a website. The ones with no site are your prospects; the full count is your Island Audit statistic.
B9: 3. | C9: Use the dropdowns in Sector, District, Priority, Channel and Status — the Dashboard only counts correctly if you do.
B10: 4. | C10: Update Status as you go. Log each touch date in the Touch 1-5 columns.
B11: 5. | C11: The 'Dashboard' tab calculates itself. Check it every Friday.
B12: 6. | C12: 'Sectors' tab = your target priority list and the search terms to use on Google Maps.
B13: 7. | C13: 'Send Log' tab = daily email volume and deliverability. Watch the bounce rate — over 3% means stop and fix.
B15: THE TWO NUMBERS THAT MATTER MOST
B16: Reply rate | C16: Under 2% after 300 emails = your first line isn't specific enough, or you have no demo link, or you're in spam. Check in that order.
B17: Bounce rate | C17: Over 3% = stop sending immediately. Verify your list before you damage the sending domain.
B19: PRIORITY TIERS
B20: Tier A | C20: Tours, watersports, guesthouses, vacation rentals, non-strip restaurants. Build a real demo before emailing.
B21: Tier B | C21: Trades, contractors, auto services, professional services. Generic sector demo with their name dropped in.
B22: Tier C | C22: Retail, salons, gyms, everyone else. No demo — use a Google search screenshot instead.
B24: STATUS MEANINGS
B25: Not started | C25: Logged, not yet contacted
B26: Sequenced | C26: In the 5-touch email sequence
B27: Replied | C27: They responded — reply within 2 hours
B28: Meeting booked | C28: Get off email and into a room. This is the goal of every email.
B29: Proposal sent | C29: Showed them the three tiers
B30: Won | C30: Signed. Log deal value + monthly.
B31: Lost | C31: No, for now. Revisit in 6 months.
B32: Unsubscribed | C32: Asked to be removed. Never contact again.

Sheet Dashboard
B2: DASHBOARD
B3: Calculates automatically from the Prospects tab. Review every Friday.
B5: THE ISLAND AUDIT
B6: Businesses logged | D6: =COUNTA(Prospects!B4:B800) -> 1
B7: With no website | D7: =COUNTIF(Prospects!I4:I800,"No") -> 1
B8: % with no website | D8: =IFERROR(D7/D6,0) -> 1 | E8: <-- this is your local statistic. Quote it in every pitch.
B9: Have a site but not mobile-friendly | D9: =COUNTIF(Prospects!J4:J800,"No") -> 0 | E9: Rebuild prospects
B10: No Google Business Profile | D10: =COUNTIF(Prospects!K4:K800,"No") -> 1 | E10: Fastest visible win you can sell
B12: PIPELINE
B13: Not started | D13: =COUNTIF(Prospects!U4:U800,"Not started") -> 0
B14: In sequence | D14: =COUNTIF(Prospects!U4:U800,"Sequenced") -> 0
B15: Replied | D15: =COUNTIF(Prospects!U4:U800,"Replied") -> 1
B16: Meetings booked | D16: =COUNTIF(Prospects!U4:U800,"Meeting booked") -> 0
B17: Proposals sent | D17: =COUNTIF(Prospects!U4:U800,"Proposal sent") -> 0
B18: WON | D18: =COUNTIF(Prospects!U4:U800,"Won") -> 0
B19: Lost | D19: =COUNTIF(Prospects!U4:U800,"Lost") -> 0
B20: Unsubscribed | D20: =COUNTIF(Prospects!U4:U800,"Unsubscribed") -> 0 | E20: Never contact again
B22: REVENUE
B23: Build fees won | D23: =SUMIF(Prospects!U4:U800,"Won",Prospects!V4:V800) -> 0
B24: Monthly recurring won | D24: =SUMIF(Prospects!U4:U800,"Won",Prospects!W4:W800) -> 0
B25: Annual recurring run-rate | D25: =D24*12 -> 0
B26: Total booked (yr 1) | D26: =D23+D25 -> 0
B27: Avg build fee per client | D27: =IFERROR(D23/D18,0) -> 0 | E27: If under $500 you are discounting too hard
B29: CONVERSION
B30: Contacted (all touched) | D30: =D6-D13 -> 1
B31: Reply rate | D31: =IFERROR((D15+D16+D17+D18+D19)/D30,0) -> 1 | E31: Benchmark 3.4%. Good is 6%+.
B32: Contacted -> meeting | D32: =IFERROR((D16+D17+D18)/D30,0) -> 0 | E32: Target 2-3%
B33: Meeting -> won | D33: =IFERROR(D18/(D16+D17+D18+D19),0) -> 0 | E33: Target 30%. With a demo built, 50%+.
B35: BY PRIORITY TIER
B36: Tier A logged | D36: =COUNTIF(Prospects!L4:L800,"Tier A") -> 1
B37: Tier B logged | D37: =COUNTIF(Prospects!L4:L800,"Tier B") -> 0
B38: Tier C logged | D38: =COUNTIF(Prospects!L4:L800,"Tier C") -> 0
B39: Tier A won | D39: =COUNTIFS(Prospects!L4:L800,"Tier A",Prospects!U4:U800,"Won") -> 0
B41: BY SECTOR — where you are actually winning
B42: Sector | C42: Logged | D42: No site | E42: Won
B43: Tours & Watersports | C43: =COUNTIF(Prospects!$C$4:$C$800,$B43) -> 1 | D43: =COUNTIFS(Prospects!$C$4:$C$800,$B43,Prospects!$I$4:$I$800,"No") -> 1 | E43: =COUNTIFS(Prospects!$C$4:$C$800,$B43,Prospects!$U$4:$U$800,"Won") -> 0
B44: Guesthouse / Rental | C44: =COUNTIF(Prospects!$C$4:$C$800,$B44) -> 0 | D44: =COUNTIFS(Prospects!$C$4:$C$800,$B44,Prospects!$I$4:$I$800,"No") -> 0 | E44: =COUNTIFS(Prospects!$C$4:$C$800,$B44,Prospects!$U$4:$U$800,"Won") -> 0
B45: Restaurant / Bar | C45: =COUNTIF(Prospects!$C$4:$C$800,$B45) -> 0 | D45: =COUNTIFS(Prospects!$C$4:$C$800,$B45,Prospects!$I$4:$I$800,"No") -> 0 | E45: =COUNTIFS(Prospects!$C$4:$C$800,$B45,Prospects!$U$4:$U$800,"Won") -> 0
B46: Food Truck | C46: =COUNTIF(Prospects!$C$4:$C$800,$B46) -> 0 | D46: =COUNTIFS(Prospects!$C$4:$C$800,$B46,Prospects!$I$4:$I$800,"No") -> 0 | E46: =COUNTIFS(Prospects!$C$4:$C$800,$B46,Prospects!$U$4:$U$800,"Won") -> 0
B47: Trades / Contractor | C47: =COUNTIF(Prospects!$C$4:$C$800,$B47) -> 0 | D47: =COUNTIFS(Prospects!$C$4:$C$800,$B47,Prospects!$I$4:$I$800,"No") -> 0 | E47: =COUNTIFS(Prospects!$C$4:$C$800,$B47,Prospects!$U$4:$U$800,"Won") -> 0
...

Sheet Prospects
A1: PROSPECTS — blue text columns are for you to fill in
A2: Row 4 is an example. Delete it when you start.
A3: ID | B3: Business Name | C3: Sector | D3: District | E3: Owner Name | F3: Phone / WhatsApp | G3: Email | H3: Facebook / IG | I3: Has Website? | J3: Mobile OK? | K3: Google Profile? | L3: Priority | M3: Demo Built? | N3: Demo Link | O3: Channel | P3: Touch 1 | Q3: Touch 2 | R3: Touch 3 | S3: Touch 4 | T3: Touch 5 | U3: Status | V3: Deal $ | W3: Monthly $ | X3: Notes
A4: 1 | B4: Playa Snorkel Tours | C4: Tours & Watersports | D4: Noord | E4: Ricardo | F4: +297 593 1234 | G4: info@playasnorkel.aw | H4: fb.com/playasnorkel | I4: No | J4: N/A | K4: No | L4: Tier A | M4: Yes | N4: demo.mysite.com/playa | O4: Email | P4: 2026-09-01 | Q4: 2026-09-05 | R4: 2026-09-09 | U4: Replied | V4: 500 | W4: 20 | X4: Pays Viator 20% — lead with the commission argument

Sheet Sectors
B2: TARGET SECTORS — ranked, with Google Maps search terms
B3: Work top to bottom. Tier A first — best ROI story, easiest close.
B5: Tier | C5: Sector | D5: Why they buy | E5: Search terms for Google Maps | F5: Est. % with no site
B6: A | C6: Tours & Watersports | D6: Pays Viator/TripAdvisor 20-30% commission. One direct booking pays the year. | E6: snorkel tour aruba / UTV tour / sunset sail / dive shop / kitesurf / fishing charter | F6: High
B7: A | C7: Guesthouse / Rental | D7: Pays Booking.com & Airbnb 15-18%. Direct booking form is pure margin. | E7: guesthouse aruba / apartment rental aruba / vacation rental / B&B | F7: High
B8: A | C8: Restaurant / Bar | D8: Menu is a Facebook photo — Google can't read it. Tourists search 'restaurants near me'. | E8: restaurant oranjestad / bar noord / seafood aruba / local food aruba | F8: 35-42%
B9: A | C9: Food Truck | D9: Location + hours change constantly. A live page beats a buried FB post. | E9: food truck aruba / snack aruba / truck di cuminda | F9: High
B10: B | C10: Trades / Contractor | D10: Highest no-website rate anywhere. Locals search at 11pm when it breaks. Best retention. | E10: ac repair aruba / plumber aruba / electrician / pool service / roofing / solar | F10: 45-56%
B11: B | C11: Auto / Car Rental | D11: Independents lose every tourist search to Hertz and Avis. | E11: car rental aruba / scooter rental / mechanic aruba / tyre shop / body shop | F11: 38-51%
B12: B | C12: Professional Services | D12: Credibility is the product. 75% judge a business by its site. Highest ability to pay. | E12: accountant aruba / lawyer / notary / insurance broker / translator | F12: 15-25%
B13: B | C13: Health / Clinic | D13: Same credibility argument. Slower sale, better client. | E13: dentist aruba / physio / vet aruba / clinic | F13: 20-30%
B14: C | C14: Retail / Boutique | D14: Lower ticket, but visual and good for your portfolio. | E14: boutique aruba / gift shop / mini market / jewellery | F14: 40-48%
B15: C | C15: Salon / Barber | D15: Price-sensitive and high churn — take them, don't chase them. | E15: salon aruba / barber aruba / nails / spa | F15: 38-44%
B16: C | C16: Gym / Fitness | D16: Class schedules and pricing pages sell themselves. | E16: gym aruba / crossfit / yoga aruba | F16: Medium
B17: C | C17: Events / Wedding | D17: Tourist-driven and high-ticket, but seasonal. | E17: wedding planner aruba / photographer aruba / event rental | F17: Medium
B20: Skip: large resorts, AHATA hotel members, franchise/chain outlets, anything where the person you're emailing isn't the owner.
B21: 'Est. % with no site' figures are global industry benchmarks, not Aruba-measured. Replace them with your own Island Audit numbers as you build the list.

Sheet Send Log
B2: DAILY SEND LOG
B3: Log every sending day. Blue = you type it. Grey = calculated.
B5: Date | C5: Sent | D5: Bounced | E5: Replies | F5: Positive | G5: Meetings booked | H5: Bounce % | I5: Reply %
B6: 2026-09-01 | C6: 25 | D6: 0 | E6: 1 | F6: 1 | G6: 0 | H6: =IFERROR(D6/C6,"") -> 0 | I6: =IFERROR(E6/C6,"") -> 0.04
H7: =IFERROR(D7/C7,"") | I7: =IFERROR(E7/C7,"")
H8: =IFERROR(D8/C8,"") | I8: =IFERROR(E8/C8,"")
H9: =IFERROR(D9/C9,"") | I9: =IFERROR(E9/C9,"")
H10: =IFERROR(D10/C10,"") | I10: =IFERROR(E10/C10,"")
H11: =IFERROR(D11/C11,"") | I11: =IFERROR(E11/C11,"")
H12: =IFERROR(D12/C12,"") | I12: =IFERROR(E12/C12,"")
H13: =IFERROR(D13/C13,"") | I13: =IFERROR(E13/C13,"")
H14: =IFERROR(D14/C14,"") | I14: =IFERROR(E14/C14,"")
H15: =IFERROR(D15/C15,"") | I15: =IFERROR(E15/C15,"")
H16: =IFERROR(D16/C16,"") | I16: =IFERROR(E16/C16,"")
H17: =IFERROR(D17/C17,"") | I17: =IFERROR(E17/C17,"")
H18: =IFERROR(D18/C18,"") | I18: =IFERROR(E18/C18,"")
... H205: =IFERROR(D205/C205,"") | I205: =IFERROR(E205/C205,"")
B207: TOTAL | C207: =SUM(C6:C205) -> 25 | D207: =SUM(D6:D205) -> 0 | E207: =SUM(E6:E205) -> 1 | F207: =SUM(F6:F205) -> 1 | G207: =SUM(G6:G205) -> 0 | H207: =IFERROR(D207/C207,"") -> 0 | I207: =IFERROR(E207/C207,"") -> 0.04
B209: STOP SENDING if bounce % goes over 3% or you get spam complaints. Verify the list, then restart slowly.
B210: Safe volume: 20-30/day for Aruba. Never exceed 100/day per mailbox; over 150/day raises spam rates 43%.
